Workbook

Sheet Read me
A1: Plant the Forest - Balancing Sheet
A2: Change the blue numbers; every black number recalculates.
A4: Color key
A5: Blue text = an input you can change.
A6: Black text = a formula. Do not type over these.
A7: Yellow fill = the key result to watch (minutes to fill each forest).
A9: Tabs
A10: Inputs - global settings, including the Strength-to-capacity and Speed-to-walk-speed curves.
A11: Rarity - hexes per tree, coin multiplier per seed, and seed odds.
A12: Capacity - what Strength does, giant-seed size milestones, training times, and a check against recorded pyramid stats.
A13: Walk Speed - what Speed does, with the same pyramid check.
A14: Biomes - the two forest tiers (same map, re-themed): seeds per hex and the estimated time to fill each forest. Tune this tab first.
... A27: All numbers are starting guesses to replace with real playtest data.

Sheet Inputs
A1: Global inputs
A3: Setting | B3: Value | C3: Notes
A4: Active players per server | B4: 30 | C4: Players actively planting, not just online. Max server size is 50; most servers should sit around 35, with about 30 planting at any moment.
A5: Base walk speed (studs/s) | B5: 32 | C5: Walk speed at 0 Speed. The pyramid game starts players at 32 (Roblox default is 16).
A6: Max walk speed bonus (studs/s) | B6: 28 | C6: Walk speed approaches base + this but never reaches it (60 here).
A7: Speed for half the bonus | B7: 230 | C7: At this Speed stat, players get half the bonus. Lower = faster early gains.
A8: Capacity curve: a | B8: 19.3 | C8: Scale of the Strength-to-capacity curve. Fitted to pyramid readings.
A9: Capacity curve: k | B9: 37 | C9: Controls how steep the first few levels are.
A10: Capacity curve: q | B10: 0.256 | C10: Long-term compression. Lower = stats inflate more for each extra seed.
A11: Training rate (stat/s at 1x) | B11: 1 | C11: Automatic: stand on the bench press or treadmill. Planting gives no stats.
A12: Hex size (studs, center to corner) | B12: 5 | C12: Neighbor trees are 1.73 x this apart.
A13: Average ring spacing (studs) | B13: =B12*1.6 -> 8 | C13: Approximation: rings sit 1.5 to 1.73 hex sizes apart.
A14: Hub radius (hex rings, no planting) | B14: 5 | C14: Empty clearing in the middle for the seed rack, shops and Training Grove.
A15: No-plant share (paths, stream) | B15: 0.1 | C15: Share of forest hexes lost to paths and water.
A16: Time to grab seeds (s) | B16: 1 | C16: At the seed rack, averaged for a player with some Bulk Pickup. Without upgrades it is 1 seed per press; holding E repeats.
A17: Time to plant a load (s) | B17: 0.5 | C17: Averaged for a player with some Bulk Plant. Without upgrades it is 1 seed per press; holding E repeats.

Sheet Rarity
A1: Rarity values (backlog, not in the first version)
A3: Rarity | B3: Hexes per tree | C3: Coin multiplier per seed | D3: Base odds (per new tree) | E3: Hexes x odds | F3: Hexes x coins x odds
A4: Common | B4: 1 | C4: 1 | D4: 0.8767 | E4: =B4*D4 -> 0.8767 | F4: =B4*C4*D4 -> 0.8767
A5: Uncommon | B5: 1 | C5: 1.5 | D5: 0.1 | E5: =B5*D5 -> 0.1 | F5: =B5*C5*D5 -> 0.15
A6: Rare | B6: 1 | C6: 2 | D6: 0.02 | E6: =B6*D6 -> 0.02 | F6: =B6*C6*D6 -> 0.04
A7: Epic | B7: 1 | C7: 3 | D7: 0.003 | E7: =B7*D7 -> 0.003 | F7: =B7*C7*D7 -> 0.009
A8: Legendary | B8: 1 | C8: 5 | D8: 0.0003 | E8: =B8*D8 -> 0.0003 | F8: =B8*C8*D8 -> 0.0015
A9: Mythic | B9: 1 | C9: 10 | D9: 0 | E9: =B9*D9 -> 0 | F9: =B9*C9*D9 -> 0
A10: Total | D10: =SUM(D4:D9) -> 1
A12: Average hexes per tree | B12: =SUM(E4:E9)/D10 -> 1
A13: Average coins per seed | B13: =SUM(F4:F9)/SUM(E4:E9) -> 1.0772
A15: Every tree takes exactly one hex. Rarity is rolled when the first seed lands in an empty hex; every seed earns 1 coin x that tree's multiplier. Mythic trees come only from events. Until rarity ships, every tree is Common.

Sheet Capacity
A1: Strength to seed capacity
A2: Gym multiplier: | D2: 1 | E2: 2 | F2: 5 | G2: 10 | H2: 25
A3: Strength | B3: Seeds per trip | C3: Strength per +1 seed here | D3: Minutes to train at 1x | E3: at 2x | F3: at 5x | G3: at 10x | H3: at 25x
A4: 0 | B4: =ROUND(1+Inputs!$B$8*((1+(A4)/Inputs!$B$9)^Inputs!$B$10-1),0) -> 1 | C4: =1/(Inputs!$B$8*Inputs!$B$10/Inputs!$B$9*(1+A4/Inputs!$B$9)^(Inputs!$B$10-1)) -> 7.4886658 | D4: =A4/(Inputs!$B$11*D$2)/60 -> 0 | E4: =A4/(Inputs!$B$11*E$2)/60 -> 0 | F4: =A4/(Inputs!$B$11*F$2)/60 -> 0 | G4: =A4/(Inputs!$B$11*G$2)/60 -> 0 | H4: =A4/(Inputs!$B$11*H$2)/60 -> 0
A5: 7 | B5: =ROUND(1+Inputs!$B$8*((1+(A5)/Inputs!$B$9)^Inputs!$B$10-1),0) -> 2 | C5: =1/(Inputs!$B$8*Inputs!$B$10/Inputs!$B$9*(1+A5/Inputs!$B$9)^(Inputs!$B$10-1)) -> 8.5190498 | D5: =A5/(Inputs!$B$11*D$2)/60 -> 0.11666667 | E5: =A5/(Inputs!$B$11*E$2)/60 -> 0.058333333 | F5: =A5/(Inputs!$B$11*F$2)/60 -> 0.023333333 | G5: =A5/(Inputs!$B$11*G$2)/60 -> 0.011666667 | H5: =A5/(Inputs!$B$11*H$2)/60 -> 0.0046666667
A6: 28 | B6: =ROUND(1+Inputs!$B$8*((1+(A6)/Inputs!$B$9)^Inputs!$B$10-1),0) -> 4 | C6: =1/(Inputs!$B$8*Inputs!$B$10/Inputs!$B$9*(1+A6/Inputs!$B$9)^(Inputs!$B$10-1)) -> 11.388589 | D6: =A6/(Inputs!$B$11*D$2)/60 -> 0.46666667 | E6: =A6/(Inputs!$B$11*E$2)/60 -> 0.23333333 | F6: =A6/(Inputs!$B$11*F$2)/60 -> 0.093333333 | G6: =A6/(Inputs!$B$11*G$2)/60 -> 0.046666667 | H6: =A6/(Inputs!$B$11*H$2)/60 -> 0.018666667
A7: 55 | B7: =ROUND(1+Inputs!$B$8*((1+(A7)/Inputs!$B$9)^Inputs!$B$10-1),0) -> 6 | C7: =1/(Inputs!$B$8*Inputs!$B$10/Inputs!$B$9*(1+A7/Inputs!$B$9)^(Inputs!$B$10-1)) -> 14.747572 | D7: =A7/(Inputs!$B$11*D$2)/60 -> 0.91666667 | E7: =A7/(Inputs!$B$11*E$2)/60 -> 0.45833333 | F7: =A7/(Inputs!$B$11*F$2)/60 -> 0.18333333 | G7: =A7/(Inputs!$B$11*G$2)/60 -> 0.091666667 | H7: =A7/(Inputs!$B$11*H$2)/60 -> 0.036666667
A8: 100 | B8: =ROUND(1+Inputs!$B$8*((1+(A8)/Inputs!$B$9)^Inputs!$B$10-1),0) -> 9 | C8: =1/(Inputs!$B$8*Inputs!$B$10/Inputs!$B$9*(1+A8/Inputs!$B$9)^(Inputs!$B$10-1)) -> 19.832729 | D8: =A8/(Inputs!$B$11*D$2)/60 -> 1.6666667 | E8: =A8/(Inputs!$B$11*E$2)/60 -> 0.83333333 | F8: =A8/(Inputs!$B$11*F$2)/60 -> 0.33333333 | G8: =A8/(Inputs!$B$11*G$2)/60 -> 0.16666667 | H8: =A8/(Inputs!$B$11*H$2)/60 -> 0.066666667
A9: 250 | B9: =ROUND(1+Inputs!$B$8*((1+(A9)/Inputs!$B$9)^Inputs!$B$10-1),0) -> 14 | C9: =1/(Inputs!$B$8*Inputs!$B$10/Inputs!$B$9*(1+A9/Inputs!$B$9)^(Inputs!$B$10-1)) -> 34.381633 | D9: =A9/(Inputs!$B$11*D$2)/60 -> 4.1666667 | E9: =A9/(Inputs!$B$11*E$2)/60 -> 2.0833333 | F9: =A9/(Inputs!$B$11*F$2)/60 -> 0.83333333 | G9: =A9/(Inputs!$B$11*G$2)/60 -> 0.41666667 | H9: =A9/(Inputs!$B$11*H$2)/60 -> 0.16666667
A10: 500 | B10: =ROUND(1+Inputs!$B$8*((1+(A10)/Inputs!$B$9)^Inputs!$B$10-1),0) -> 20 | C10: =1/(Inputs!$B$8*Inputs!$B$10/Inputs!$B$9*(1+A10/Inputs!$B$9)^(Inputs!$B$10-1)) -> 54.797814 | D10: =A10/(Inputs!$B$11*D$2)/60 -> 8.3333333 | E10: =A10/(Inputs!$B$11*E$2)/60 -> 4.1666667 | F10: =A10/(Inputs!$B$11*F$2)/60 -> 1.6666667 | G10: =A10/(Inputs!$B$11*G$2)/60 -> 0.83333333 | H10: =A10/(Inputs!$B$11*H$2)/60 -> 0.33333333
A11: 1000 | B11: =ROUND(1+Inputs!$B$8*((1+(A11)/Inputs!$B$9)^Inputs!$B$10-1),0) -> 27 | C11: =1/(Inputs!$B$8*Inputs!$B$10/Inputs!$B$9*(1+A11/Inputs!$B$9)^(Inputs!$B$10-1)) -> 89.413225 | D11: =A11/(Inputs!$B$11*D$2)/60 -> 16.666667 | E11: =A11/(Inputs!$B$11*E$2)/60 -> 8.3333333 | F11: =A11/(Inputs!$B$11*F$2)/60 -> 3.3333333 | G11: =A11/(Inputs!$B$11*G$2)/60 -> 1.6666667 | H11: =A11/(Inputs!$B$11*H$2)/60 -> 0.66666667
A12: 2386 | B12: =ROUND(1+Inputs!$B$8*((1+(A12)/Inputs!$B$9)^Inputs!$B$10-1),0) -> 38 | C12: =1/(Inputs!$B$8*Inputs!$B$10/Inputs!$B$9*(1+A12/Inputs!$B$9)^(Inputs!$B$10-1)) -> 168.12075 | D12: =A12/(Inputs!$B$11*D$2)/60 -> 39.766667 | E12: =A12/(Inputs!$B$11*E$2)/60 -> 19.883333 | F12: =A12/(Inputs!$B$11*F$2)/60 -> 7.9533333 | G12: =A12/(Inputs!$B$11*G$2)/60 -> 3.9766667 | H12: =A12/(Inputs!$B$11*H$2)/60 -> 1.5906667
A13: 5000 | B13: =ROUND(1+Inputs!$B$8*((1+(A13)/Inputs!$B$9)^Inputs!$B$10-1),0) -> 50 | C13: =1/(Inputs!$B$8*Inputs!$B$10/Inputs!$B$9*(1+A13/Inputs!$B$9)^(Inputs!$B$10-1)) -> 289.7866 | D13: =A13/(Inputs!$B$11*D$2)/60 -> 83.333333 | E13: =A13/(Inputs!$B$11*E$2)/60 -> 41.666667 | F13: =A13/(Inputs!$B$11*F$2)/60 -> 16.666667 | G13: =A13/(Inputs!$B$11*G$2)/60 -> 8.3333333 | H13: =A13/(Inputs!$B$11*H$2)/60 -> 3.3333333
A14: 10000 | B14: =ROUND(1+Inputs!$B$8*((1+(A14)/Inputs!$B$9)^Inputs!$B$10-1),0) -> 63 | C14: =1/(Inputs!$B$8*Inputs!$B$10/Inputs!$B$9*(1+A14/Inputs!$B$9)^(Inputs!$B$10-1)) -> 484.01151 | D14: =A14/(Inputs!$B$11*D$2)/60 -> 166.66667 | E14: =A14/(Inputs!$B$11*E$2)/60 -> 83.333333 | F14: =A14/(Inputs!$B$11*F$2)/60 -> 33.333333 | G14: =A14/(Inputs!$B$11*G$2)/60 -> 16.666667 | H14: =A14/(Inputs!$B$11*H$2)/60 -> 6.6666667
A15: 25000 | B15: =ROUND(1+Inputs!$B$8*((1+(A15)/Inputs!$B$9)^Inputs!$B$10-1),0) -> 84 | C15: =1/(Inputs!$B$8*Inputs!$B$10/Inputs!$B$9*(1+A15/Inputs!$B$9)^(Inputs!$B$10-1)) -> 955.44918 | D15: =A15/(Inputs!$B$11*D$2)/60 -> 416.66667 | E15: =A15/(Inputs!$B$11*E$2)/60 -> 208.33333 | F15: =A15/(Inputs!$B$11*F$2)/60 -> 83.333333 | G15: =A15/(Inputs!$B$11*G$2)/60 -> 41.666667 | H15: =A15/(Inputs!$B$11*H$2)/60 -> 16.666667
... A20: 1000000 | B20: =ROUND(1+Inputs!$B$8*((1+(A20)/Inputs!$B$9)^Inputs!$B$10-1),0) -> 245 | C20: =1/(Inputs!$B$8*Inputs!$B$10/Inputs!$B$9*(1+A20/Inputs!$B$9)^(Inputs!$B$10-1)) -> 14848.218 | D20: =A20/(Inputs!$B$11*D$2)/60 -> 16666.667 | E20: =A20/(Inputs!$B$11*E$2)/60 -> 8333.3333 | F20: =A20/(Inputs!$B$11*F$2)/60 -> 3333.3333 | G20: =A20/(Inputs!$B$11*G$2)/60 -> 1666.6667 | H20: =A20/(Inputs!$B$11*H$2)/60 -> 666.66667
A22: Giant seed size milestones
A23: Seeds held | B23: Strength needed | C23: How the giant seed looks
A24: 1 | B24: =ROUND(Inputs!$B$9*(((A24-1)/Inputs!$B$8+1)^(1/Inputs!$B$10)-1),0) -> 0 | C24: An acorn the size of your head
A25: 5 | B25: =ROUND(Inputs!$B$9*(((A25-1)/Inputs!$B$8+1)^(1/Inputs!$B$10)-1),0) -> 40 | C25: As big as your whole body
A26: 15 | B26: =ROUND(Inputs!$B$9*(((A26-1)/Inputs!$B$8+1)^(1/Inputs!$B$10)-1),0) -> 275 | C26: Twice your height
A27: 40 | B27: =ROUND(Inputs!$B$9*(((A27-1)/Inputs!$B$8+1)^(1/Inputs!$B$10)-1),0) -> 2740 | C27: The size of a car
A28: 80 | B28: =ROUND(Inputs!$B$9*(((A28-1)/Inputs!$B$8+1)^(1/Inputs!$B$10)-1),0) -> 21338 | C28: The size of a house
A29: 150 | B29: =ROUND(Inputs!$B$9*(((A29-1)/Inputs!$B$8+1)^(1/Inputs!$B$10)-1),0) -> 174599 | C29: Blocks out the sun
A30: 250 | B30: =ROUND(Inputs!$B$9*(((A30-1)/Inputs!$B$8+1)^(1/Inputs!$B$10)-1),0) -> 1079638 | C30: Casts a shadow over the whole hub
A32: Check: recorded Build the Pyramid stats vs this curve
A33: Strength | B33: Recorded capacity | C33: Curve gives | D33: Difference
A34: 0 | B34: 1 | C34: =ROUND(1+Inputs!$B$8*((1+(A34)/Inputs!$B$9)^Inputs!$B$10-1),0) -> 1 | D34: =C34-B34 -> 0
A35: 7 | B35: 2 | C35: =ROUND(1+Inputs!$B$8*((1+(A35)/Inputs!$B$9)^Inputs!$B$10-1),0) -> 2 | D35: =C35-B35 -> 0
A36: 28 | B36: 4 | C36: =ROUND(1+Inputs!$B$8*((1+(A36)/Inputs!$B$9)^Inputs!$B$10-1),0) -> 4 | D36: =C36-B36 -> 0
A37: 40 | B37: 5 | C37: =ROUND(1+Inputs!$B$8*((1+(A37)/Inputs!$B$9)^Inputs!$B$10-1),0) -> 5 | D37: =C37-B37 -> 0
A38: 55 | B38: 6 | C38: =ROUND(1+Inputs!$B$8*((1+(A38)/Inputs!$B$9)^Inputs!$B$10-1),0) -> 6 | D38: =C38-B38 -> 0
A39: 1000 | B39: 27 | C39: =ROUND(1+Inputs!$B$8*((1+(A39)/Inputs!$B$9)^Inputs!$B$10-1),0) -> 27 | D39: =C39-B39 -> 0
A40: 1090 | B40: 28 | C40: =ROUND(1+Inputs!$B$8*((1+(A40)/Inputs!$B$9)^Inputs!$B$10-1),0) -> 28 | D40: =C40-B40 -> 0
A41: 1190 | B41: 29 | C41: =ROUND(1+Inputs!$B$8*((1+(A41)/Inputs!$B$9)^Inputs!$B$10-1),0) -> 29 | D41: =C41-B41 -> 0
A42: 2386 | B42: 38 | C42: =ROUND(1+Inputs!$B$8*((1+(A42)/Inputs!$B$9)^Inputs!$B$10-1),0) -> 38 | D42: =C42-B42 -> 0
A44: Training multipliers (unlocked by forests completed)
A45: Forests done | B45: Gym multiplier
A46: 0 | B46: 1
A47: 1 | B47: 2
...

Sheet Walk Speed
A1: Speed stat to walk speed
A3: Speed stat | B3: Walk speed (studs/s) | C3: Minutes to train at 1x | D3: Seconds to cross 100 studs | E3: Recorded in pyramid
A4: 0 | B4: =Inputs!$B$5+Inputs!$B$6*(A4)/((A4)+Inputs!$B$7) -> 32 | C4: =A4/Inputs!$B$11/60 -> 0 | D4: =100/B4 -> 3.125 | E4: 32
A5: 9 | B5: =Inputs!$B$5+Inputs!$B$6*(A5)/((A5)+Inputs!$B$7) -> 33.054393 | C5: =A5/Inputs!$B$11/60 -> 0.15 | D5: =100/B5 -> 3.0253165 | E5: 33
A6: 18 | B6: =Inputs!$B$5+Inputs!$B$6*(A6)/((A6)+Inputs!$B$7) -> 34.032258 | C6: =A6/Inputs!$B$11/60 -> 0.3 | D6: =100/B6 -> 2.9383886 | E6: 34
A7: 27 | B7: =Inputs!$B$5+Inputs!$B$6*(A7)/((A7)+Inputs!$B$7) -> 34.941634 | C7: =A7/Inputs!$B$11/60 -> 0.45 | D7: =100/B7 -> 2.8619154 | E7: 35
A8: 100 | B8: =Inputs!$B$5+Inputs!$B$6*(A8)/((A8)+Inputs!$B$7) -> 40.484848 | C8: =A8/Inputs!$B$11/60 -> 1.6666667 | D8: =100/B8 -> 2.4700599
A9: 230 | B9: =Inputs!$B$5+Inputs!$B$6*(A9)/((A9)+Inputs!$B$7) -> 46 | C9: =A9/Inputs!$B$11/60 -> 3.8333333 | D9: =100/B9 -> 2.173913
A10: 579 | B10: =Inputs!$B$5+Inputs!$B$6*(A10)/((A10)+Inputs!$B$7) -> 52.039555 | C10: =A10/Inputs!$B$11/60 -> 9.65 | D10: =100/B10 -> 1.9216152 | E10: 52
A11: 1000 | B11: =Inputs!$B$5+Inputs!$B$6*(A11)/((A11)+Inputs!$B$7) -> 54.764228 | C11: =A11/Inputs!$B$11/60 -> 16.666667 | D11: =100/B11 -> 1.8260095
A12: 2000 | B12: =Inputs!$B$5+Inputs!$B$6*(A12)/((A12)+Inputs!$B$7) -> 57.112108 | C12: =A12/Inputs!$B$11/60 -> 33.333333 | D12: =100/B12 -> 1.7509422
A13: 5000 | B13: =Inputs!$B$5+Inputs!$B$6*(A13)/((A13)+Inputs!$B$7) -> 58.768642 | C13: =A13/Inputs!$B$11/60 -> 83.333333 | D13: =100/B13 -> 1.7015877
A14: 10000 | B14: =Inputs!$B$5+Inputs!$B$6*(A14)/((A14)+Inputs!$B$7) -> 59.370479 | C14: =A14/Inputs!$B$11/60 -> 166.66667 | D14: =100/B14 -> 1.6843388
A15: 50000 | B15: =Inputs!$B$5+Inputs!$B$6*(A15)/((A15)+Inputs!$B$7) -> 59.87179 | C15: =A15/Inputs!$B$11/60 -> 833.33333 | D15: =100/B15 -> 1.6702357

Sheet Biomes
A1: Forest tiers: size and fill time
A2: Both tiers use the same map and the same hex grid, re-themed. The server loops back to tier 1 after tier 2. Tune the blue columns until "Minutes to fill" sits around 12.
A4: # | B4: Forest tier | C4: Forest rings (same map) | D4: Seeds per hex | E4: Typical Strength | F4: Typical Speed | G4: Seeds per trip | H4: Walk speed | I4: Plantable hexes | J4: Estimated trees | K4: Seeds to fill (Forest Bar target) | L4: Outer edge (studs) | M4: Avg trip distance (studs) | N4: Trip time (s) | O4: Minutes to fill | P4: Coins per player per min | Q4: Check
A5: 1 | B5: Meadow Woods | C5: 28 | D5: 8 | E5: 150 | F5: 100 | G5: =ROUND(1+Inputs!$B$8*((1+(E5)/Inputs!$B$9)^Inputs!$B$10-1),0) -> 11 | H5: =Inputs!$B$5+Inputs!$B$6*(F5)/((F5)+Inputs!$B$7) -> 40.484848 | I5: =ROUND((3*(Inputs!$B$14+C5)*((Inputs!$B$14+C5)+1)+1-(3*Inputs!$B$14*(Inputs!$B$14+1)+1))*(1-Inputs!$B$15),0) -> 2948 | J5: =ROUND(I5/Rarity!$B$12,0) -> 2948 | K5: =I5*D5 -> 23584 | L5: =(Inputs!$B$14+C5)*Inputs!$B$13 -> 264 | M5: =2/3*(L5^3-(Inputs!$B$14*Inputs!$B$13)^3)/(L5^2-(Inputs!$B$14*Inputs!$B$13)^2) -> 179.50877 | N5: =2*M5/H5+Inputs!$B$16+Inputs!$B$17 -> 10.367948 | O5: =K5/(G5*60/N5*Inputs!$B$4) -> 12.349378 | P5: =G5*60/N5*Rarity!$B$13 -> 68.572101 | Q5: =IF(J5>5000,"Test performance: >5,000 trees",IF(OR(O5<9,O5>15),"Fill time outside 9 to 15 min","OK")) -> OK
A6: 2 | B6: Cherry Blossom Valley | C6: 28 | D6: 21 | E6: 800 | F6: 300 | G6: =ROUND(1+Inputs!$B$8*((1+(E6)/Inputs!$B$9)^Inputs!$B$10-1),0) -> 25 | H6: =Inputs!$B$5+Inputs!$B$6*(F6)/((F6)+Inputs!$B$7) -> 47.849057 | I6: =ROUND((3*(Inputs!$B$14+C6)*((Inputs!$B$14+C6)+1)+1-(3*Inputs!$B$14*(Inputs!$B$14+1)+1))*(1-Inputs!$B$15),0) -> 2948 | J6: =ROUND(I6/Rarity!$B$12,0) -> 2948 | K6: =I6*D6 -> 61908 | L6: =(Inputs!$B$14+C6)*Inputs!$B$13 -> 264 | M6: =2/3*(L6^3-(Inputs!$B$14*Inputs!$B$13)^3)/(L6^2-(Inputs!$B$14*Inputs!$B$13)^2) -> 179.50877 | N6: =2*M6/H6+Inputs!$B$16+Inputs!$B$17 -> 9.0031269 | O6: =K6/(G6*60/N6*Inputs!$B$4) -> 12.385902 | P6: =G6*60/N6*Rarity!$B$13 -> 179.47098 | Q6: =IF(J6>5000,"Test performance: >5,000 trees",IF(OR(O6<9,O6>15),"Fill time outside 9 to 15 min","OK")) -> OK
A8: Average trip distance assumes rings fill from the hub outward (area-weighted average across the forest).
A9: Targets are fixed. As players get stronger over many loops, forests finish faster, like a veteran pyramid server finishing in about 6 minutes.
A10: Seeds per hex: each seed grows a tree one stage, so a hex is complete after this many seeds. Rare trees need hexes x seeds per hex.

Sheet Upgrades
A1: Coin upgrades
A2: Cost of level n = base cost x growth ^ (n - 1).
A4: Upgrade | B4: Effect per level | C4: Base cost | D4: Growth | E4: Max level | F4: Lvl 1 | G4: Lvl 2 | H4: Lvl 3 | I4: Lvl 4 | J4: Lvl 5 | K4: Total to max
A5: Bulk Pickup | B5: Grabs 2 / 4 / 8 / 16 / all seeds per press at the rack (hold E to repeat) | C5: 50 | D5: 4 | E5: 5 | F5: =IF(1<=E5,ROUND(C5*D5^(1-1),0),"") -> 50 | G5: =IF(2<=E5,ROUND(C5*D5^(2-1),0),"") -> 200 | H5: =IF(3<=E5,ROUND(C5*D5^(3-1),0),"") -> 800 | I5: =IF(4<=E5,ROUND(C5*D5^(4-1),0),"") -> 3200 | J5: =IF(5<=E5,ROUND(C5*D5^(5-1),0),"") -> 12800 | K5: =SUM(F5:J5) -> 17050
A6: Bulk Plant | B6: Plants 2 / 4 / 8 / 16 / all seeds per press (hold E to repeat) | C6: 50 | D6: 4 | E6: 5 | F6: =IF(1<=E6,ROUND(C6*D6^(1-1),0),"") -> 50 | G6: =IF(2<=E6,ROUND(C6*D6^(2-1),0),"") -> 200 | H6: =IF(3<=E6,ROUND(C6*D6^(3-1),0),"") -> 800 | I6: =IF(4<=E6,ROUND(C6*D6^(4-1),0),"") -> 3200 | J6: =IF(5<=E6,ROUND(C6*D6^(5-1),0),"") -> 12800 | K6: =SUM(F6:J6) -> 17050
A7: Quick Hands | B7: Planting animation 15% faster per level | C7: 100 | D7: 3 | E7: 5 | F7: =IF(1<=E7,ROUND(C7*D7^(1-1),0),"") -> 100 | G7: =IF(2<=E7,ROUND(C7*D7^(2-1),0),"") -> 300 | H7: =IF(3<=E7,ROUND(C7*D7^(3-1),0),"") -> 900 | I7: =IF(4<=E7,ROUND(C7*D7^(4-1),0),"") -> 2700 | J7: =IF(5<=E7,ROUND(C7*D7^(5-1),0),"") -> 8100 | K7: =SUM(F7:J7) -> 12100
A8: Seed Pouch (backlog) | B8: +5 storage slots for shop seeds per level | C8: 75 | D8: 3 | E8: 5 | F8: =IF(1<=E8,ROUND(C8*D8^(1-1),0),"") -> 75 | G8: =IF(2<=E8,ROUND(C8*D8^(2-1),0),"") -> 225 | H8: =IF(3<=E8,ROUND(C8*D8^(3-1),0),"") -> 675 | I8: =IF(4<=E8,ROUND(C8*D8^(4-1),0),"") -> 2025 | J8: =IF(5<=E8,ROUND(C8*D8^(5-1),0),"") -> 6075 | K8: =SUM(F8:J8) -> 9075
A9: Planting Range | B9: +2 studs reach to snap onto a plot per level | C9: 60 | D9: 3 | E9: 5 | F9: =IF(1<=E9,ROUND(C9*D9^(1-1),0),"") -> 60 | G9: =IF(2<=E9,ROUND(C9*D9^(2-1),0),"") -> 180 | H9: =IF(3<=E9,ROUND(C9*D9^(3-1),0),"") -> 540 | I9: =IF(4<=E9,ROUND(C9*D9^(4-1),0),"") -> 1620 | J9: =IF(5<=E9,ROUND(C9*D9^(5-1),0),"") -> 4860 | K9: =SUM(F9:J9) -> 7260
A10: Lucky Soil (backlog) | B10: +2% relative rarity luck per level | C10: 500 | D10: 4 | E10: 5 | F10: =IF(1<=E10,ROUND(C10*D10^(1-1),0),"") -> 500 | G10: =IF(2<=E10,ROUND(C10*D10^(2-1),0),"") -> 2000 | H10: =IF(3<=E10,ROUND(C10*D10^(3-1),0),"") -> 8000 | I10: =IF(4<=E10,ROUND(C10*D10^(4-1),0),"") -> 32000 | J10: =IF(5<=E10,ROUND(C10*D10^(5-1),0),"") -> 128000 | K10: =SUM(F10:J10) -> 170500
A12: Compare 'Total to max' with 'Coins per player per min' on the Biomes tab to see how many minutes of play each upgrade line costs.

Sheet Weather
A1: Weather events and mutations
A3: Minutes between events | B3: 10
A4: Event length (minutes) | B4: 2.5
A5: Share of play time with an event active | B5: =B4/(B3+B4) -> 0.2
A7: Event | B7: Mutation | C7: Coin multiplier | D7: Chance per tree | E7: Pick weight | F7: Expected bonus per tree
A8: Rain | B8: Wet | C8: 2 | D8: 0.2 | E8: 40 | F8: =(C8-1)*D8 -> 0.2
A9: Snowfall | B9: Frozen | C9: 3 | D9: 0.12 | E9: 25 | F9: =(C9-1)*D9 -> 0.24
A10: Thunderstorm | B10: Shocked | C10: 5 | D10: 0.06 | E10: 20 | F10: =(C10-1)*D10 -> 0.24
A11: Meteor shower | B11: Cosmic | C11: 10 | D11: 0.03 | E11: 10 | F11: =(C11-1)*D11 -> 0.27
A12: Golden hour | B12: Golden | C12: 20 | D12: 0.01 | E12: 5 | F12: =(C12-1)*D12 -> 0.19
A14: Coin boost from planting during an average event | B14: =SUMPRODUCT(E8:E12,F8:F12)/SUM(E8:E12) -> 0.2245
A15: Coin boost averaged over all play time | B15: =B14*B5 -> 0.0449
A17: A tree rolls for a mutation when its first seed lands during an event. Expected bonus = extra coins relative to an unmutated tree.
